<?xml version="1.0" encoding="UTF-8"?>
<!-- Generated by org.testng.reporters.JUnitXMLReporter -->
<testsuite hostname="C3DES396" ignored="0" name="TC_12_Install_CF_with_5Gbits" tests="1" failures="1" timestamp="04 Dec 2017 07:28:24 GMT" time="320.74" errors="0">
  <testcase name="@AfterTest Aftertest" time="0.0" classname="TestDriver.TestExecutionDriver">
    <failure type="java.lang.IllegalArgumentException" message="wrong number of arguments">
      <![CDATA[java.lang.IllegalArgumentException: wrong number of arguments
	at java.util.concurrent.FutureTask.run(Unknown Source)
	at java.util.concurrent.ThreadPoolExecutor.runWorker(Unknown Source)
	at java.util.concurrent.ThreadPoolExecutor$Worker.run(Unknown Source)
	at java.lang.Thread.run(Unknown Source)
... Removed 14 stack frames]]>
    </failure>
  </testcase> <!-- @AfterTest Aftertest -->
  <testcase name="TestCaseExecution" time="266.708" classname="TestDriver.TestExecutionDriver">
    <failure type="java.lang.AssertionError" message="expected [Ready for Order] but found [Customer Approved]">
      <![CDATA[java.lang.AssertionError: expected [Ready for Order] but found [Customer Approved]
	at com.test.automation.OM_Automation.uiActions.SubOrders.OrderStageValidation(SubOrders.java:176)
	at com.test.automation.OM_Automation.uiActions.SubOrders.CreatedOrderValidation(SubOrders.java:120)
	at DUMMYDELETEIT.genericDriver.subOrdersValidationAndClosure(genericDriver.java:561)
	at TestDriver.TestExecutionDriver.TestCaseExecution(TestExecutionDriver.java:178)
	at java.util.concurrent.FutureTask.run(Unknown Source)
	at java.util.concurrent.ThreadPoolExecutor.runWorker(Unknown Source)
	at java.util.concurrent.ThreadPoolExecutor$Worker.run(Unknown Source)
	at java.lang.Thread.run(Unknown Source)
... Removed 22 stack frames]]>
    </failure>
  </testcase> <!-- TestCaseExecution -->
</testsuite> <!-- TC_12_Install_CF_with_5Gbits -->
